<mujoco model="g1_29dof_rev_1_0">
  <compiler angle="radian" meshdir="../meshes/"/>

  <asset>
    <mesh name="pelvis" content_type="model/stl" file="pelvis.STL"/>
    <mesh name="pelvis_contour_link" content_type="model/stl" file="pelvis_contour_link.STL"/>
    <mesh name="left_hip_pitch_link" content_type="model/stl" file="left_hip_pitch_link.STL"/>
    <mesh name="left_hip_roll_link" content_type="model/stl" file="left_hip_roll_link.STL"/>
    <mesh name="left_hip_yaw_link" content_type="model/stl" file="left_hip_yaw_link.STL"/>
    <mesh name="left_knee_link" content_type="model/stl" file="left_knee_link.STL"/>
    <mesh name="left_ankle_pitch_link" content_type="model/stl" file="left_ankle_pitch_link.STL"/>
    <mesh name="left_ankle_roll_link" content_type="model/stl" file="left_ankle_roll_link.STL"/>
    <mesh name="right_hip_pitch_link" content_type="model/stl" file="right_hip_pitch_link.STL"/>
    <mesh name="right_hip_roll_link" content_type="model/stl" file="right_hip_roll_link.STL"/>
    <mesh name="right_hip_yaw_link" content_type="model/stl" file="right_hip_yaw_link.STL"/>
    <mesh name="right_knee_link" content_type="model/stl" file="right_knee_link.STL"/>
    <mesh name="right_ankle_pitch_link" content_type="model/stl" file="right_ankle_pitch_link.STL"/>
    <mesh name="right_ankle_roll_link" content_type="model/stl" file="right_ankle_roll_link.STL"/>
    <mesh name="waist_yaw_link_rev_1_0" content_type="model/stl" file="waist_yaw_link_rev_1_0.STL"/>
    <mesh name="waist_roll_link_rev_1_0" content_type="model/stl" file="waist_roll_link_rev_1_0.STL"/>
    <mesh name="torso_link_rev_1_0" content_type="model/stl" file="torso_link_rev_1_0.STL"/>
    <mesh name="logo_link" content_type="model/stl" file="logo_link.STL"/>
    <mesh name="head_link" content_type="model/stl" file="head_link.STL"/>
    <mesh name="left_shoulder_pitch_link" content_type="model/stl" file="left_shoulder_pitch_link.STL"/>
    <mesh name="left_shoulder_roll_link" content_type="model/stl" file="left_shoulder_roll_link.STL"/>
    <mesh name="left_shoulder_yaw_link" content_type="model/stl" file="left_shoulder_yaw_link.STL"/>
    <mesh name="left_elbow_link" content_type="model/stl" file="left_elbow_link.STL"/>
    <mesh name="left_wrist_roll_link" content_type="model/stl" file="left_wrist_roll_link.STL"/>
    <mesh name="left_wrist_pitch_link" content_type="model/stl" file="left_wrist_pitch_link.STL"/>
    <mesh name="left_wrist_yaw_link" content_type="model/stl" file="left_wrist_yaw_link.STL"/>
    <mesh name="left_rubber_hand" content_type="model/stl" file="left_rubber_hand.STL"/>
    <mesh name="right_shoulder_pitch_link" content_type="model/stl" file="right_shoulder_pitch_link.STL"/>
    <mesh name="right_shoulder_roll_link" content_type="model/stl" file="right_shoulder_roll_link.STL"/>
    <mesh name="right_shoulder_yaw_link" content_type="model/stl" file="right_shoulder_yaw_link.STL"/>
    <mesh name="right_elbow_link" content_type="model/stl" file="right_elbow_link.STL"/>
    <mesh name="right_wrist_roll_link" content_type="model/stl" file="right_wrist_roll_link.STL"/>
    <mesh name="right_wrist_pitch_link" content_type="model/stl" file="right_wrist_pitch_link.STL"/>
    <mesh name="right_wrist_yaw_link" content_type="model/stl" file="right_wrist_yaw_link.STL"/>
    <mesh name="right_rubber_hand" content_type="model/stl" file="right_rubber_hand.STL"/>
  </asset>

  <worldbody>
    <body name="pelvis">
      <inertial pos="0 0 -0.0760301" quat="1 0 -0.000398273 0" mass="3.814" diaginertia="0.0105549 0.00931478 0.0079185"/>
      <joint name="floating_base_joint" type="free"/>
      <geom type="mesh" contype="0" conaffinity="0" group="1" density="0" rgba="0.2 0.2 0.2 1" mesh="pelvis"/>
      <geom type="mesh" contype="0" conaffinity="0" group="1" density="0" rgba="0.7 0.7 0.7 1" mesh="pelvis_contour_link"/>
      <geom type="mesh" rgba="0.7 0.7 0.7 1" mesh="pelvis_contour_link"/>
      <body name="left_hip_pitch_link" pos="0 0.064452 -0.1027">
        <inertial pos="0.002741 0.047791 -0.02606" quat="0.954862 0.293964 0.0302556 0.030122" mass="1.35" diaginertia="0.00181517 0.00153422 0.00116212"/>
        <joint name="left_hip_pitch_joint" pos="0 0 0" axis="0 1 0" range="-2.5307 2.8798" actuatorfrcrange="-88 88"/>
        <geom type="mesh" contype="0" conaffinity="0" group="1" density="0" rgba="0.2 0.2 0.2 1" mesh="left_hip_pitch_link"/>
        <body name="left_hip_roll_link" pos="0 0.052 -0.030465" quat="0.996179 0 -0.0873386 0">
          <inertial pos="0.029812 -0.001045 -0.087934" quat="0.977808 -1.97119e-05 0.205576 -0.0403793" mass="1.52" diaginertia="0.00254986 0.00241169 0.00148755"/>
          <joint name="left_hip_roll_joint" pos="0 0 0" axis="1 0 0" range="-0.5236 2.9671" actuatorfrcrange="-139 139"/>
          <geom type="mesh" contype="0" conaffinity="0" group="1" density="0" rgba="0.7 0.7 0.7 1" mesh="left_hip_roll_link"/>
          <geom type="mesh" rgba="0.7 0.7 0.7 1" mesh="left_hip_roll_link"/>
          <body name="left_hip_yaw_link" pos="0.025001 0 -0.12412">
            <inertial pos="-0.057709 -0.010981 -0.15078" quat="0.600598 0.15832 0.223482 0.751181" mass="1.702" diaginertia="0.00776166 0.00717575 0.00160139"/>
            <joint name="left_hip_yaw_joint" pos="0 0 0" axis="0 0 1" range="-2.7576 2.7576" actuatorfrcrange="-88 88"/>
            <geom type="mesh" contype="0" conaffinity="0" group="1" density="0" rgba="0.7 0.7 0.7 1" mesh="left_hip_yaw_link"/>
            <geom type="mesh" rgba="0.7 0.7 0.7 1" mesh="left_hip_yaw_link"/>
            <body name="left_knee_link" pos="-0.078273 0.0021489 -0.17734" quat="0.996179 0 0.0873386 0">
              <inertial pos="0.005457 0.003964 -0.12074" quat="0.923418 -0.0327699 0.0158246 0.382067" mass="1.932" diaginertia="0.0113804 0.0112778 0.00146458"/>
              <joint name="left_knee_joint" pos="0 0 0" axis="0 1 0" range="-0.087267 2.8798" actuatorfrcrange="-139 139"/>
              <geom type="mesh" contype="0" conaffinity="0" group="1" density="0" rgba="0.7 0.7 0.7 1" mesh="left_knee_link"/>
              <geom size="0.05 0.04 0.075" pos="0.01 0.005 -0.1" type="box" rgba="0.7 0.7 0.7 1"/>
              <geom size="0.025 0.025 0.05" pos="0.005 0.005 -0.21" type="box" rgba="0.7 0.7 0.7 1"/>
              <body name="left_ankle_pitch_link" pos="0 -9.4445e-05 -0.30001">
                <inertial pos="-0.007269 0 0.011137" quat="0.603053 0.369225 0.369225 0.603053" mass="0.074" diaginertia="1.89e-05 1.40805e-05 6.9195e-06"/>
                <joint name="left_ankle_pitch_joint" pos="0 0 0" axis="0 1 0" range="-0.87267 0.5236" actuatorfrcrange="-50 50"/>
                <geom type="mesh" contype="0" conaffinity="0" group="1" density="0" rgba="0.7 0.7 0.7 1" mesh="left_ankle_pitch_link"/>
                <geom type="mesh" rgba="0.7 0.7 0.7 1" mesh="left_ankle_pitch_link"/>
                <body name="left_ankle_roll_link" pos="0 0 -0.017558">
                  <inertial pos="0.026505 0 -0.016425" quat="-0.000481092 0.728482 -0.000618967 0.685065" mass="0.608" diaginertia="0.00167218 0.0016161 0.000217621"/>
                  <joint name="left_ankle_roll_joint" pos="0 0 0" axis="1 0 0" range="-0.2618 0.2618" actuatorfrcrange="-50 50"/>
                  <geom type="mesh" contype="0" conaffinity="0" group="1" density="0" rgba="0.2 0.2 0.2 1" mesh="left_ankle_roll_link"/>
                  <geom type="mesh" rgba="0.2 0.2 0.2 1" mesh="left_ankle_roll_link"/>
                </body>
              </body>
            </body>
          </body>
        </body>
      </body>
      <body name="right_hip_pitch_link" pos="0 -0.064452 -0.1027">
        <inertial pos="0.002741 -0.047791 -0.02606" quat="0.954862 -0.293964 0.0302556 -0.030122" mass="1.35" diaginertia="0.00181517 0.00153422 0.00116212"/>
        <joint name="right_hip_pitch_joint" pos="0 0 0" axis="0 1 0" range="-2.5307 2.8798" actuatorfrcrange="-88 88"/>
        <geom type="mesh" contype="0" conaffinity="0" group="1" density="0" rgba="0.2 0.2 0.2 1" mesh="right_hip_pitch_link"/>
        <body name="right_hip_roll_link" pos="0 -0.052 -0.030465" quat="0.996179 0 -0.0873386 0">
          <inertial pos="0.029812 0.001045 -0.087934" quat="0.977808 1.97119e-05 0.205576 0.0403793" mass="1.52" diaginertia="0.00254986 0.00241169 0.00148755"/>
          <joint name="right_hip_roll_joint" pos="0 0 0" axis="1 0 0" range="-2.9671 0.5236" actuatorfrcrange="-139 139"/>
          <geom type="mesh" contype="0" conaffinity="0" group="1" density="0" rgba="0.7 0.7 0.7 1" mesh="right_hip_roll_link"/>
          <geom type="mesh" rgba="0.7 0.7 0.7 1" mesh="right_hip_roll_link"/>
          <body name="right_hip_yaw_link" pos="0.025001 0 -0.12412">
            <inertial pos="-0.057709 0.010981 -0.15078" quat="0.751181 0.223482 0.15832 0.600598" mass="1.702" diaginertia="0.00776166 0.00717575 0.00160139"/>
            <joint name="right_hip_yaw_joint" pos="0 0 0" axis="0 0 1" range="-2.7576 2.7576" actuatorfrcrange="-88 88"/>
            <geom type="mesh" contype="0" conaffinity="0" group="1" density="0" rgba="0.7 0.7 0.7 1" mesh="right_hip_yaw_link"/>
            <geom type="mesh" rgba="0.7 0.7 0.7 1" mesh="right_hip_yaw_link"/>
            <body name="right_knee_link" pos="-0.078273 -0.0021489 -0.17734" quat="0.996179 0 0.0873386 0">
              <inertial pos="0.005457 -0.003964 -0.12074" quat="0.923439 0.0345276 0.0116333 -0.382012" mass="1.932" diaginertia="0.011374 0.0112843 0.00146452"/>
              <joint name="right_knee_joint" pos="0 0 0" axis="0 1 0" range="-0.087267 2.8798" actuatorfrcrange="-139 139"/>
              <geom type="mesh" contype="0" conaffinity="0" group="1" density="0" rgba="0.7 0.7 0.7 1" mesh="right_knee_link"/>
              <geom size="0.05 0.04 0.075" pos="0.01 0.005 -0.1" type="box" rgba="0.7 0.7 0.7 1"/>
              <geom size="0.025 0.025 0.05" pos="0.005 0.005 -0.21" type="box" rgba="0.7 0.7 0.7 1"/>
              <body name="right_ankle_pitch_link" pos="0 9.4445e-05 -0.30001">
                <inertial pos="-0.007269 0 0.011137" quat="0.603053 0.369225 0.369225 0.603053" mass="0.074" diaginertia="1.89e-05 1.40805e-05 6.9195e-06"/>
                <joint name="right_ankle_pitch_joint" pos="0 0 0" axis="0 1 0" range="-0.87267 0.5236" actuatorfrcrange="-50 50"/>
                <geom type="mesh" contype="0" conaffinity="0" group="1" density="0" rgba="0.7 0.7 0.7 1" mesh="right_ankle_pitch_link"/>
                <body name="right_ankle_roll_link" pos="0 0 -0.017558">
                  <inertial pos="0.026505 0 -0.016425" quat="0.000481092 0.728482 0.000618967 0.685065" mass="0.608" diaginertia="0.00167218 0.0016161 0.000217621"/>
                  <joint name="right_ankle_roll_joint" pos="0 0 0" axis="1 0 0" range="-0.2618 0.2618" actuatorfrcrange="-50 50"/>
                  <geom type="mesh" contype="0" conaffinity="0" group="1" density="0" rgba="0.2 0.2 0.2 1" mesh="right_ankle_roll_link"/>
                  <geom type="mesh" rgba="0.2 0.2 0.2 1" mesh="right_ankle_roll_link"/>
                </body>
              </body>
            </body>
          </body>
        </body>
      </body>
      <body name="waist_yaw_link">
        <inertial pos="0.000177223 -0.000106723 0.220705" quat="0.999885 -0.00451048 0.0142507 0.00245485" mass="8.117" diaginertia="0.135582 0.12343 0.0277371"/>
        <joint name="waist_yaw_joint" pos="0 0 0" axis="0 0 1" range="-2.618 2.618" actuatorfrcrange="-88 88"/>
        <geom type="mesh" contype="0" conaffinity="0" group="1" density="0" rgba="0.7 0.7 0.7 1" mesh="waist_yaw_link_rev_1_0"/>
        <geom pos="-0.0039635 0 0.044" quat="1 0 0 0" type="mesh" contype="0" conaffinity="0" group="1" density="0" rgba="0.7 0.7 0.7 1" mesh="waist_roll_link_rev_1_0"/>
        <geom pos="-0.0039635 0 0.044" type="mesh" contype="0" conaffinity="0" group="1" density="0" rgba="0.7 0.7 0.7 1" mesh="torso_link_rev_1_0"/>
        <geom pos="-0.0039635 0 0.044" type="mesh" rgba="0.7 0.7 0.7 1" mesh="torso_link_rev_1_0"/>
        <geom type="mesh" contype="0" conaffinity="0" group="1" density="0" rgba="0.2 0.2 0.2 1" mesh="logo_link"/>
        <geom type="mesh" contype="0" conaffinity="0" group="1" density="0" rgba="0.2 0.2 0.2 1" mesh="head_link"/>
        <geom type="mesh" rgba="0.2 0.2 0.2 1" mesh="head_link"/>
        <body name="left_shoulder_pitch_link" pos="-7.2e-06 0.10022 0.29178" quat="0.990264 0.139201 1.38722e-05 -9.86868e-05">
          <inertial pos="0 0.035892 -0.011628" quat="0.654152 0.0130458 -0.326267 0.68225" mass="0.718" diaginertia="0.000465864 0.000432842 0.000406394"/>
          <joint name="left_shoulder_pitch_joint" pos="0 0 0" axis="0 1 0" range="-3.0892 2.6704" actuatorfrcrange="-25 25"/>
          <geom type="mesh" contype="0" conaffinity="0" group="1" density="0" rgba="0.7 0.7 0.7 1" mesh="left_shoulder_pitch_link"/>
          <body name="left_shoulder_roll_link" pos="0 0.038 -0.013831" quat="0.990268 -0.139172 0 0">
            <inertial pos="-0.000227 0.00727 -0.063243" quat="0.701256 -0.0196223 -0.00710317 0.712604" mass="0.643" diaginertia="0.000691311 0.000618011 0.000388977"/>
            <joint name="left_shoulder_roll_joint" pos="0 0 0" axis="1 0 0" range="-1.5882 2.2515" actuatorfrcrange="-25 25"/>
            <geom type="mesh" contype="0" conaffinity="0" group="1" density="0" rgba="0.7 0.7 0.7 1" mesh="left_shoulder_roll_link"/>
            <body name="left_shoulder_yaw_link" pos="0 0.00624 -0.1032">
              <inertial pos="0.010773 -0.002949 -0.072009" quat="0.716879 -0.0964829 -0.0679942 0.687134" mass="0.734" diaginertia="0.00106187 0.00103217 0.000400661"/>
              <joint name="left_shoulder_yaw_joint" pos="0 0 0" axis="0 0 1" range="-2.618 2.618" actuatorfrcrange="-25 25"/>
              <geom type="mesh" contype="0" conaffinity="0" group="1" density="0" rgba="0.7 0.7 0.7 1" mesh="left_shoulder_yaw_link"/>
              <geom type="mesh" rgba="0.7 0.7 0.7 1" mesh="left_shoulder_yaw_link"/>
              <body name="left_elbow_link" pos="0.015783 0 -0.080518">
                <inertial pos="0.064956 0.004454 -0.010062" quat="0.541765 0.636132 0.388821 0.388129" mass="0.6" diaginertia="0.000443035 0.000421612 0.000259353"/>
                <joint name="left_elbow_joint" pos="0 0 0" axis="0 1 0" range="-1.0472 2.0944" actuatorfrcrange="-25 25"/>
                <geom type="mesh" contype="0" conaffinity="0" group="1" density="0" rgba="0.7 0.7 0.7 1" mesh="left_elbow_link"/>
                <geom type="mesh" rgba="0.7 0.7 0.7 1" mesh="left_elbow_link"/>
                <body name="left_wrist_roll_link" pos="0.1 0.00188791 -0.01">
                  <inertial pos="0.0331563 0.0486591 0.0174574" quat="0.632183 0.289317 -0.607515 0.384143" mass="0.824071" diaginertia="0.00260559 0.00230131 0.000871837"/>
                  <joint name="left_wrist_roll_joint" pos="0 0 0" axis="1 0 0" range="-1.97222 1.97222" actuatorfrcrange="-25 25"/>
                  <geom type="mesh" contype="0" conaffinity="0" group="1" density="0" rgba="0.7 0.7 0.7 1" mesh="left_wrist_roll_link"/>
                  <geom type="mesh" rgba="0.7 0.7 0.7 1" mesh="left_wrist_roll_link"/>
                  <geom pos="0.038 0 0" quat="1 0 0 0" type="mesh" contype="0" conaffinity="0" group="1" density="0" rgba="0.7 0.7 0.7 1" mesh="left_wrist_pitch_link"/>
                  <geom pos="0.038 0 0" quat="1 0 0 0" type="mesh" rgba="0.7 0.7 0.7 1" mesh="left_wrist_pitch_link"/>
                  <geom pos="0.084 0 0" quat="1 0 0 0" type="mesh" contype="0" conaffinity="0" group="1" density="0" rgba="0.7 0.7 0.7 1" mesh="left_wrist_yaw_link"/>
                  <geom pos="0.084 0 0" quat="1 0 0 0" type="mesh" rgba="0.7 0.7 0.7 1" mesh="left_wrist_yaw_link"/>
                  <geom pos="0.1255 0.003 0" quat="1 0 0 0" type="mesh" contype="0" conaffinity="0" group="1" density="0" rgba="0.7 0.7 0.7 1" mesh="left_rubber_hand"/>
                  <geom pos="0.1255 0.003 0" quat="1 0 0 0" type="mesh" rgba="0.7 0.7 0.7 1" mesh="left_rubber_hand"/>
                </body>
              </body>
            </body>
          </body>
        </body>
        <body name="right_shoulder_pitch_link" pos="-7.2e-06 -0.10021 0.29178" quat="0.990264 -0.139201 1.38722e-05 9.86868e-05">
          <inertial pos="0 -0.035892 -0.011628" quat="0.68225 -0.326267 0.0130458 0.654152" mass="0.718" diaginertia="0.000465864 0.000432842 0.000406394"/>
          <joint name="right_shoulder_pitch_joint" pos="0 0 0" axis="0 1 0" range="-3.0892 2.6704" actuatorfrcrange="-25 25"/>
          <geom type="mesh" contype="0" conaffinity="0" group="1" density="0" rgba="0.7 0.7 0.7 1" mesh="right_shoulder_pitch_link"/>
          <body name="right_shoulder_roll_link" pos="0 -0.038 -0.013831" quat="0.990268 0.139172 0 0">
            <inertial pos="-0.000227 -0.00727 -0.063243" quat="0.712604 -0.00710317 -0.0196223 0.701256" mass="0.643" diaginertia="0.000691311 0.000618011 0.000388977"/>
            <joint name="right_shoulder_roll_joint" pos="0 0 0" axis="1 0 0" range="-2.2515 1.5882" actuatorfrcrange="-25 25"/>
            <geom type="mesh" contype="0" conaffinity="0" group="1" density="0" rgba="0.7 0.7 0.7 1" mesh="right_shoulder_roll_link"/>
            <body name="right_shoulder_yaw_link" pos="0 -0.00624 -0.1032">
              <inertial pos="0.010773 0.002949 -0.072009" quat="0.687134 -0.0679942 -0.0964829 0.716879" mass="0.734" diaginertia="0.00106187 0.00103217 0.000400661"/>
              <joint name="right_shoulder_yaw_joint" pos="0 0 0" axis="0 0 1" range="-2.618 2.618" actuatorfrcrange="-25 25"/>
              <geom type="mesh" contype="0" conaffinity="0" group="1" density="0" rgba="0.7 0.7 0.7 1" mesh="right_shoulder_yaw_link"/>
              <geom type="mesh" rgba="0.7 0.7 0.7 1" mesh="right_shoulder_yaw_link"/>
              <body name="right_elbow_link" pos="0.015783 0 -0.080518">
                <inertial pos="0.064956 -0.004454 -0.010062" quat="0.388129 0.388821 0.636132 0.541765" mass="0.6" diaginertia="0.000443035 0.000421612 0.000259353"/>
                <joint name="right_elbow_joint" pos="0 0 0" axis="0 1 0" range="-1.0472 2.0944" actuatorfrcrange="-25 25"/>
                <geom type="mesh" contype="0" conaffinity="0" group="1" density="0" rgba="0.7 0.7 0.7 1" mesh="right_elbow_link"/>
                <geom type="mesh" rgba="0.7 0.7 0.7 1" mesh="right_elbow_link"/>
                <body name="right_wrist_roll_link" pos="0.1 -0.00188791 -0.01">
                  <inertial pos="0.0240543 0.050979 -0.0177697" quat="0.511048 0.540113 -0.537609 0.397598" mass="0.824071" diaginertia="0.00232024 0.00202614 0.000887032"/>
                  <joint name="right_wrist_roll_joint" pos="0 0 0" axis="1 0 0" range="-1.97222 1.97222" actuatorfrcrange="-25 25"/>
                  <geom type="mesh" contype="0" conaffinity="0" group="1" density="0" rgba="0.7 0.7 0.7 1" mesh="right_wrist_roll_link"/>
                  <geom type="mesh" rgba="0.7 0.7 0.7 1" mesh="right_wrist_roll_link"/>
                  <geom pos="0.038 0 0" quat="1 0 0 0" type="mesh" contype="0" conaffinity="0" group="1" density="0" rgba="0.7 0.7 0.7 1" mesh="right_wrist_pitch_link"/>
                  <geom pos="0.038 0 0" quat="1 0 0 0" type="mesh" rgba="0.7 0.7 0.7 1" mesh="right_wrist_pitch_link"/>
                  <geom pos="0.084 0 0" quat="1 0 0 0" type="mesh" contype="0" conaffinity="0" group="1" density="0" rgba="0.7 0.7 0.7 1" mesh="right_wrist_yaw_link"/>
                  <geom pos="0.084 0 0" quat="1 0 0 0" type="mesh" rgba="0.7 0.7 0.7 1" mesh="right_wrist_yaw_link"/>
                  <geom pos="0.1255 -0.003 0" quat="1 0 0 0" type="mesh" contype="0" conaffinity="0" group="1" density="0" rgba="0.7 0.7 0.7 1" mesh="right_rubber_hand"/>
                  <geom pos="0.1255 -0.003 0" quat="1 0 0 0" type="mesh" rgba="0.7 0.7 0.7 1" mesh="right_rubber_hand"/>
                </body>
              </body>
            </body>
          </body>
        </body>
      </body>
    </body>
  </worldbody>
</mujoco>
